2024-07-17 16:31:08,710 INFO    StreamThr :48000 [internal.py:wandb_internal():85] W&B internal server running at pid: 48000, started at: 2024-07-17 16:31:08.709454
2024-07-17 16:31:08,710 DEBUG   HandlerThread:48000 [handler.py:handle_request():158] handle_request: status
2024-07-17 16:31:08,719 INFO    WriterThread:48000 [datastore.py:open_for_write():87] open: ./wandb/run-20240717_163108-2bt72vx3/run-2bt72vx3.wandb
2024-07-17 16:31:08,719 DEBUG   SenderThread:48000 [sender.py:send():379] send: header
2024-07-17 16:31:08,737 DEBUG   SenderThread:48000 [sender.py:send():379] send: run
2024-07-17 16:31:08,738 INFO    SenderThread:48000 [sender.py:_setup_resume():749] checking resume status for Guillermo Rambo/capdock_torsion/2bt72vx3
2024-07-17 16:31:08,899 ERROR   SenderThread:48000 [internal_api.py:execute():349] 404 response executing GraphQL.
2024-07-17 16:31:08,899 ERROR   SenderThread:48000 [internal_api.py:execute():350] {"errors":[{"message":"entity Guillermo Rambo not found during upsertBucket","path":["upsertBucket"]}],"data":{"upsertBucket":null}}
2024-07-17 16:31:08,899 ERROR   SenderThread:48000 [sender.py:send_run():1009] It appears that you do not have permission to access the requested resource. Please reach out to the project owner to grant you access. If you have the correct permissions, verify that there are no issues with your networking setup.(Error 404: Not Found)
Traceback (most recent call last):
  File "/Users/scanner1/opt/anaconda3/envs/capdock/lib/python3.9/site-packages/wandb/sdk/lib/retry.py", line 131, in __call__
    result = self._call_fn(*args, **kwargs)
  File "/Users/scanner1/opt/anaconda3/envs/capdock/lib/python3.9/site-packages/wandb/sdk/internal/internal_api.py", line 345, in execute
    return self.client.execute(*args, **kwargs)  # type: ignore
  File "/Users/scanner1/opt/anaconda3/envs/capdock/lib/python3.9/site-packages/wandb/vendor/gql-0.2.0/wandb_gql/client.py", line 52, in execute
    result = self._get_result(document, *args, **kwargs)
  File "/Users/scanner1/opt/anaconda3/envs/capdock/lib/python3.9/site-packages/wandb/vendor/gql-0.2.0/wandb_gql/client.py", line 60, in _get_result
    return self.transport.execute(document, *args, **kwargs)
  File "/Users/scanner1/opt/anaconda3/envs/capdock/lib/python3.9/site-packages/wandb/sdk/lib/gql_request.py", line 59, in execute
    request.raise_for_status()
  File "/Users/scanner1/opt/anaconda3/envs/capdock/lib/python3.9/site-packages/requests/models.py", line 1024, in raise_for_status
    raise HTTPError(http_error_msg, response=self)
requests.exceptions.HTTPError: 404 Client Error: Not Found for url: https://api.wandb.ai/graphql

During handling of the above exception, another exception occurred:

Traceback (most recent call last):
  File "/Users/scanner1/opt/anaconda3/envs/capdock/lib/python3.9/site-packages/wandb/sdk/internal/sender.py", line 1007, in send_run
    server_run = self._init_run(run, config_value_dict)
  File "/Users/scanner1/opt/anaconda3/envs/capdock/lib/python3.9/site-packages/wandb/sdk/internal/sender.py", line 1079, in _init_run
    server_run, inserted, server_messages = self._api.upsert_run(
  File "/Users/scanner1/opt/anaconda3/envs/capdock/lib/python3.9/site-packages/wandb/apis/normalize.py", line 73, in wrapper
    raise err
  File "/Users/scanner1/opt/anaconda3/envs/capdock/lib/python3.9/site-packages/wandb/apis/normalize.py", line 41, in wrapper
    return func(*args, **kwargs)
  File "/Users/scanner1/opt/anaconda3/envs/capdock/lib/python3.9/site-packages/wandb/sdk/internal/internal_api.py", line 2224, in upsert_run
    response = self.gql(
  File "/Users/scanner1/opt/anaconda3/envs/capdock/lib/python3.9/site-packages/wandb/sdk/internal/internal_api.py", line 317, in gql
    ret = self._retry_gql(
  File "/Users/scanner1/opt/anaconda3/envs/capdock/lib/python3.9/site-packages/wandb/sdk/lib/retry.py", line 147, in __call__
    retry_timedelta_triggered = check_retry_fn(e)
  File "/Users/scanner1/opt/anaconda3/envs/capdock/lib/python3.9/site-packages/wandb/util.py", line 968, in check_retry_fn
    return fallback_retry_fn(e)
  File "/Users/scanner1/opt/anaconda3/envs/capdock/lib/python3.9/site-packages/wandb/util.py", line 910, in no_retry_auth
    raise CommError(
wandb.errors.CommError: It appears that you do not have permission to access the requested resource. Please reach out to the project owner to grant you access. If you have the correct permissions, verify that there are no issues with your networking setup.(Error 404: Not Found)
2024-07-17 16:31:08,990 DEBUG   HandlerThread:48000 [handler.py:handle_request():158] handle_request: shutdown
2024-07-17 16:31:08,990 INFO    HandlerThread:48000 [handler.py:finish():882] shutting down handler
2024-07-17 16:31:09,742 INFO    WriterThread:48000 [datastore.py:close():296] close: ./wandb/run-20240717_163108-2bt72vx3/run-2bt72vx3.wandb
2024-07-17 16:31:09,908 INFO    SenderThread:48000 [sender.py:finish():1608] shutting down sender
